Workbook

Sheet Agentes
A2: Alejandra Caceres
A3: Carlos Vargas
A4: Milenca Villarroel
A5: Andrea Carmona
A6: Valeria Terrazas
A7: Melody edezma
A8: Jose Augusto Butron
A9: Mariela Lopez
A10: Adhemar Caceres
A11: Andrea Rodriguez
A12: Daniela Gandarillas
A13: Nicolas Fernandez
... A16: Franklin Buitrago

Sheet Propiedades
A1: Codigo de propiedad | B1: Nombre | C1: Tipo | D1: Zona | E1: Precio | F1: Moneda | G1: Metros cuadrados | H1: Estado | I1: Prioridad | J1: Fotos disponibles | K1: Video Disponible | L1: Agente captador | M1: Agente vendedor | N1: Observaciones | O1: Fecha captacion | P1: Fecha cierre
A2: ="ST-" & UPPER(LEFT(B2,1)) & "-" & TEXT(COUNTIF($B$2:B2,LEFT(B2,1)&"*"),"0000") -> ST-D-0001 | B2: Departamento Freedom | C2: Alquiler | D2: Zona Norte | E2: 2200 | F2: Bs. | G2: 78 | H2: Disponible | I2: Media | J2: Si | K2: Si | L2: Alejandra Caceres | N2: Disponible a partir del 27 de abril
A3: ="ST-" & UPPER(LEFT(B3,1)) & "-" & TEXT(COUNTIF($B$2:B3,LEFT(B3,1)&"*"),"0000") -> ST-M-0001 | B3: Monoambiente Calle Beni | C3: Alquiler | D3: Zona Queru Queru | E3: 2000 | F3: Bs. | H3: No Disponible | I3: Media | J3: Si | K3: No | L3: Andrea Carmona | M3: Melody Ledezma | N3: Todo amoblado | P3: 46130
A4: ="ST-" & UPPER(LEFT(B4,1)) & "-" & TEXT(COUNTIF($B$2:B4,LEFT(B4,1)&"*"),"0000") -> ST-D-0002 | B4: Departamento 2hab. | C4: Alquiler | D4: Zona Stadium | E4: 4000 | F4: Bs. | H4: Disponible | I4: Media | J4: Si | K4: No | L4: Mariela Lopez | N4: Amoblado + expensas
A5: ="ST-" & UPPER(LEFT(B5,1)) & "-" & TEXT(COUNTIF($B$2:B5,LEFT(B5,1)&"*"),"0000") -> ST-M-0002 | B5: Monoambiente UMSS | C5: Alquiler | D5: Zona UMSS | E5: 1900 | F5: Bs. | H5: Retirado | I5: Media | J5: Si | K5: No | L5: Andrea Carmona | N5: Contrato anual
A6: ="ST-" & UPPER(LEFT(B6,1)) & "-" & TEXT(COUNTIF($B$2:B6,LEFT(B6,1)&"*"),"0000") -> ST-O-0001 | B6: Oficina centro | C6: Alquiler | D6: Zona Centro | E6: 1600 | F6: Bs. | G6: 16 | H6: Disponible | I6: Baja | J6: Si | K6: No | L6: Carlos Vargas
A7: ="ST-" & UPPER(LEFT(B7,1)) & "-" & TEXT(COUNTIF($B$2:B7,LEFT(B7,1)&"*"),"0000") -> ST-O-0002 | B7: Oficina centro | C7: Alquiler | D7: Zona Centro | E7: 1600 | F7: Bs. | G7: 16 | H7: Disponible | I7: Baja | J7: Si | K7: No | L7: Carlos Vargas
A8: ="ST-" & UPPER(LEFT(B8,1)) & "-" & TEXT(COUNTIF($B$2:B8,LEFT(B8,1)&"*"),"0000") -> ST-O-0003 | B8: Oficina centro | C8: Alquiler | D8: Zona Centro | E8: 1300 | F8: Bs. | G8: 9 | H8: Disponible | I8: Baja | J8: Si | K8: No | L8: Carlos Vargas
A9: ="ST-" & UPPER(LEFT(B9,1)) & "-" & TEXT(COUNTIF($B$2:B9,LEFT(B9,1)&"*"),"0000") -> ST-M-0003 | B9: Monoambiente Samay | C9: Alquiler | D9: Zona Stadium | E9: 2500 | F9: Bs. | H9: Disponible | I9: Alta | J9: Si | K9: No | L9: Carlos Vargas | N9: Amoblado+expensas
A10: ="ST-" & UPPER(LEFT(B10,1)) & "-" & TEXT(COUNTIF($B$2:B10,LEFT(B10,1)&"*"),"0000") -> ST-D-0003 | B10: Departamento Melchor | C10: Alquiler | D10: Zona Norte | E10: 6500 | F10: Bs. | G10: 147 | H10: Disponible | I10: Media | J10: Si | K10: Si | L10: Carlos Vargas | N10: Medidores independientes
A11: ="ST-" & UPPER(LEFT(B11,1)) & "-" & TEXT(COUNTIF($B$2:B11,LEFT(B11,1)&"*"),"0000") -> ST-L-0001 | B11: Local 25 de mayo | C11: Alquiler | D11: Zona Centro | E11: 28000 | F11: Bs. | G11: 500 | H11: Retirado | I11: Alta | J11: Si | K11: No | L11: Mariela Lopez
A12: ="ST-" & UPPER(LEFT(B12,1)) & "-" & TEXT(COUNTIF($B$2:B12,LEFT(B12,1)&"*"),"0000") -> ST-L-0002 | B12: Local Terraza Melchor Urquidi | C12: Alquiler | D12: Zona Norte | E12: 14000 | F12: Bs. | G12: 147 | H12: No Disponible | I12: Alta | J12: Si | K12: Si | L12: Carlos Vargas | M12: Yury Caceres | P12: 46121
A13: ="ST-" & UPPER(LEFT(B13,1)) & "-" & TEXT(COUNTIF($B$2:B13,LEFT(B13,1)&"*"),"0000") -> ST-O-0004 | B13: Oficina 1 Salamanca | C13: Alquiler | D13: Zona Centro | E13: 2200 | F13: Bs. | G13: 45 | H13: Disponible | I13: Alta | J13: Si | K13: No | L13: Andrea Carmona | N13: 200 EXPENSAS
A14: ="ST-" & UPPER(LEFT(B14,1)) & "-" & TEXT(COUNTIF($B$2:B14,LEFT(B14,1)&"*"),"0000") -> ST-O-0005 | B14: Oficina 2 Salamanca | C14: Alquiler | D14: Zona Centro | E14: 2200 | F14: Bs. | H14: Disponible | I14: Alta | J14: Si | K14: No | L14: Andrea Carmona
A15: ="ST-" & UPPER(LEFT(B15,1)) & "-" & TEXT(COUNTIF($B$2:B15,LEFT(B15,1)&"*"),"0000") -> ST-O-0006 | B15: Oficina 3 Salamanca | C15: Alquiler | D15: Zona Centro | E15: 2200 | F15: Bs. | H15: Disponible | I15: Alta | J15: Si | K15: No | L15: Andrea Carmona
A16: ="ST-" & UPPER(LEFT(B16,1)) & "-" & TEXT(COUNTIF($B$2:B16,LEFT(B16,1)&"*"),"0000") -> ST-O-0007 | B16: Oficina 4 Salamanca | C16: Alquiler | D16: Zona Centro | E16: 2200 | F16: Bs. | H16: Disponible | I16: Alta | J16: Si | K16: No | L16: Andrea Carmona
A17: ="ST-" & UPPER(LEFT(B17,1)) & "-" & TEXT(COUNTIF($B$2:B17,LEFT(B17,1)&"*"),"0000") -> ST-G-0001 | B17: Garzonier Salamanca | C17: Alquiler | D17: Zona Centro | E17: 2400 | F17: Bs. | H17: Disponible | I17: Alta | J17: Si | K17: No | L17: Andrea Carmona
A18: ="ST-" & UPPER(LEFT(B18,1)) & "-" & TEXT(COUNTIF($B$2:B18,LEFT(B18,1)&"*"),"0000") -> ST-P-0001 | B18: Penthouse Garden 1 | C18: Anticrético | D18: Zona Norte | E18: 200000 | F18: $ | H18: Disponible | I18: Alta | J18: Si | K18: Si | L18: Alejandra Caceres | N18: Consultar precio sin y con muebles
A19: ="ST-" & UPPER(LEFT(B19,1)) & "-" & TEXT(COUNTIF($B$2:B19,LEFT(B19,1)&"*"),"0000") -> ST-E-0001 | B19: Estacionamiento | C19: Venta | D19: Zona Norte | E19: 115000 | F19: Bs. | G19: 12.5 | H19: Disponible | I19: Alta | J19: Si | K19: No | L19: Alejandra Caceres
A20: ="ST-" & UPPER(LEFT(B20,1)) & "-" & TEXT(COUNTIF($B$2:B20,LEFT(B20,1)&"*"),"0000") -> ST-C-0001 | B20: Casa con Piscina | C20: Venta | D20: Zona Norte | E20: 2800000 | F20: Bs. | G20: 240 | H20: Disponible | I20: Media | J20: Si | K20: Si | L20: Andrea Carmona
A21: ="ST-" & UPPER(LEFT(B21,1)) & "-" & TEXT(COUNTIF($B$2:B21,LEFT(B21,1)&"*"),"0000") -> ST-C-0002 | B21: Casa Chiquicollo | C21: Venta | D21: Zona Chiquicollo | E21: 1980000 | F21: Bs. | G21: 282 | H21: Disponible | I21: Alta | J21: Si | K21: Si | L21: Alejandra Caceres | N21: Co-Captador Adhemar Caceres
A22: ="ST-" & UPPER(LEFT(B22,1)) & "-" & TEXT(COUNTIF($B$2:B22,LEFT(B22,1)&"*"),"0000") -> ST-C-0003 | B22: Casa Tadeo Haenke | C22: Venta | D22: Zona Nor-Oeste | E22: 350000 | F22: $ | G22: 420 | H22: Disponible | I22: Media | J22: Si | K22: No | L22: Adhemar Caceres | N22: Tipo de cambio paralelo
A23: ="ST-" & UPPER(LEFT(B23,1)) & "-" & TEXT(COUNTIF($B$2:B23,LEFT(B23,1)&"*"),"0000") -> ST-C-0004 | B23: Casa Jala | C23: Venta | D23: Zona Norte | E23: 535000 | F23: $ | G23: 530 | H23: Disponible | I23: Alta | J23: No | K23: No | L23: Alejandra Caceres
A24: ="ST-" & UPPER(LEFT(B24,1)) & "-" & TEXT(COUNTIF($B$2:B24,LEFT(B24,1)&"*"),"0000") -> ST-C-0005 | B24: Casa Comercial Junin | C24: Venta | D24: Zona Centro | E24: 1200000 | F24: $ | G24: 993.65 | H24: Disponible | I24: Media | J24: Si | K24: No | L24: Alejandra Caceres
A25: ="ST-" & UPPER(LEFT(B25,1)) & "-" & TEXT(COUNTIF($B$2:B25,LEFT(B25,1)&"*"),"0000") -> ST-C-0006 | B25: Casa Valle Hermoso | C25: Venta | D25: Zona Sud | E25: 315000 | F25: $ | H25: Disponible | I25: Alta | J25: Si | K25: No | L25: Alejandra Caceres
A26: ="ST-" & UPPER(LEFT(B26,1)) & "-" & TEXT(COUNTIF($B$2:B26,LEFT(B26,1)&"*"),"0000") -> ST-C-0007 | B26: Casa Condominio Victoria | C26: Venta | D26: Zona Chiquicollo | E26: 75000 | F26: $ | G26: 62 | H26: Disponible | I26: Media | J26: Si | K26: No | L26: Andrea Carmona | N26: tipo de cambio 7
A27: ="ST-" & UPPER(LEFT(B27,1)) & "-" & TEXT(COUNTIF($B$2:B27,LEFT(B27,1)&"*"),"0000") -> ST-C-0008 | B27: Casa 1 Condominio Molle | C27: Venta | D27: Zona Nor-Oeste | E27: 1860000 | F27: Bs. | H27: Disponible | I27: Alta | J27: Si | K27: Si | L27: Alejandra Caceres
A28: ="ST-" & UPPER(LEFT(B28,1)) & "-" & TEXT(COUNTIF($B$2:B28,LEFT(B28,1)&"*"),"0000") -> ST-C-0009 | B28: Casa 2 Condominio Molle | C28: Venta | D28: Zona Nor-Oeste | E28: 1800000 | F28: Bs. | H28: Disponible | I28: Alta | J28: Si | K28: Si | L28: Alejandra Caceres
A29: ="ST-" & UPPER(LEFT(B29,1)) & "-" & TEXT(COUNTIF($B$2:B29,LEFT(B29,1)&"*"),"0000") -> ST-C-0010 | B29: Casa 3 Condominio Molle | C29: Venta | D29: Zona Nor-Oeste | E29: 1780000 | F29: Bs. | H29: Disponible | I29: Alta | J29: Si | K29: Si | L29: Alejandra Caceres
A30: ="ST-" & UPPER(LEFT(B30,1)) & "-" & TEXT(COUNTIF($B$2:B30,LEFT(B30,1)&"*"),"0000") -> ST-C-0011 | B30: Casa 4 Condominio Molle | C30: Venta | D30: Zona Nor-Oeste | E30: 1990000 | F30: Bs. | H30: Disponible | I30: Alta | J30: Si | K30: Si | L30: Alejandra Caceres
A31: ="ST-" & UPPER(LEFT(B31,1)) & "-" & TEXT(COUNTIF($B$2:B31,LEFT(B31,1)&"*"),"0000") -> ST-G-0002 | B31: Garzonier Smart | C31: Venta | D31: Zona Norte | E31: 500000 | F31: Bs. | G31: 45.47 | H31: Disponible | I31: Alta | J31: Si | K31: Si | L31: Alejandra Caceres
A32: ="ST-" & UPPER(LEFT(B32,1)) & "-" & TEXT(COUNTIF($B$2:B32,LEFT(B32,1)&"*"),"0000") -> ST-M-0004 | B32: Monoambiente Torre Z | C32: Venta | D32: Zona Norte | E32: 37500 | F32: $ | G32: 23.45 | H32: Disponible | I32: Media | J32: Si | K32: No | L32: Mariela Lopez | N32: tipo de cambio 6.96
A33: ="ST-" & UPPER(LEFT(B33,1)) & "-" & TEXT(COUNTIF($B$2:B33,LEFT(B33,1)&"*"),"0000") -> ST-M-0005 | B33: Monoambiente Auriga | C33: Venta | D33: Zona Norte | E33: 310000 | F33: Bs. | G33: 18.5 | H33: Retirado | I33: Media | J33: Si | K33: No | L33: Milenca Villarroel
A34: ="ST-" & UPPER(LEFT(B34,1)) & "-" & TEXT(COUNTIF($B$2:B34,LEFT(B34,1)&"*"),"0000") -> ST-M-0006 | B34: Monoambiente Smart | C34: Venta | D34: Zona Norte | E34: 260000 | F34: Bs. | G34: 20 | H34: No Disponible | I34: Media | J34: Si | K34: No | L34: Andrea Rodriguez | M34: Yury Caceres | P34: 46128
A35: ="ST-" & UPPER(LEFT(B35,1)) & "-" & TEXT(COUNTIF($B$2:B35,LEFT(B35,1)&"*"),"0000") -> ST-P-0002 | B35: Penthouse Garden 2 | C35: Venta | D35: Zona Norte | E35: 536400 | F35: $ | G35: 298 | H35: Disponible | I35: Alta | J35: Si | K35: No | L35: Alejandra Caceres | N35: tipo de cambio 7
A36: ="ST-" & UPPER(LEFT(B36,1)) & "-" & TEXT(COUNTIF($B$2:B36,LEFT(B36,1)&"*"),"0000") -> ST-P-0003 | B36: Penthouse Garden 1 | C36: Venta | D36: Zona Norte | E36: 375000 | F36: $ | G36: 300 | H36: Disponible | I36: Alta | J36: Si | K36: Si | L36: Alejandra Caceres | N36: tipo de cambio paralelo, varia precio amoblado
A37: ="ST-" & UPPER(LEFT(B37,1)) & "-" & TEXT(COUNTIF($B$2:B37,LEFT(B37,1)&"*"),"0000") -> ST-M-0007 | B37: Monoambiente Garden | C37: Venta | D37: Zona Norte | E37: 320000 | F37: Bs. | G37: 28.25 | H37: No Disponible | I37: Media | J37: Si | K37: No | L37: Alejandra Caceres | M37: Yury Caceres | P37: 45763
A38: ="ST-" & UPPER(LEFT(B38,1)) & "-" & TEXT(COUNTIF($B$2:B38,LEFT(B38,1)&"*"),"0000") -> ST-M-0008 | B38: Monoambiente Candyl | C38: Venta | D38: Zona Norte | E38: 260000 | F38: Bs. | G38: 19 | H38: Reservado | I38: Media | J38: No | K38: No | L38: Alejandra Caceres
A39: ="ST-" & UPPER(LEFT(B39,1)) & "-" & TEXT(COUNTIF($B$2:B39,LEFT(B39,1)&"*"),"0000") -> ST-D-0004 | B39: Departamento Portales | C39: Venta | D39: Zona Norte | E39: 800000 | F39: Bs. | G39: 130 | H39: Disponible | I39: Media | J39: Si | K39: Si | L39: Rodrigo Espinoza
A40: ="ST-" & UPPER(LEFT(B40,1)) & "-" & TEXT(COUNTIF($B$2:B40,LEFT(B40,1)&"*"),"0000") -> ST-D-0005 | B40: Departamento Luxor | C40: Venta | D40: Zona Norte | E40: 700000 | F40: Bs. | G40: 87.35 | H40: Disponible | I40: Alta | J40: Si | K40: No | L40: Alejandra Caceres
...

Sheet Artes
A1: Codigo de propiedad | B1: Nombre | C1: Tipo | D1: Precio | E1: Moneda | F1: Metros cuadrados | G1: Estado | H1: Prioridad | I1: Arte 1080x1092 | J1: Arte 1080x1080 | K1: Reel | L1: Agendado | M1: Publicado
A2: =IFERROR(__xludf.DUMMYFUNCTION("FILTER({Propiedades!A:C,Propiedades!E:G,Propiedades!H:I},Propiedades!B:B<>"""")"),"#REF!") -> #REF! | I2: Arte 1080x1092 | J2: Arte 1080x1080 | K2: Reel
I3: NO | J3: NO
I4: NO | J4: NO
I5: NO | J5: NO
I6: SI | J6: SI
I7: NO | J7: NO
I8: NO | J8: NO
I9: NO | J9: NO
A10: =Propiedades!A:A -> ST-D-0003 | B10: =Propiedades!B:B -> Departamento Melchor | C10: =Propiedades!C:C -> Alquiler | D10: =Propiedades!D:D -> Zona Norte | E10: =Propiedades!E:E -> 6500 | F10: =Propiedades!F:F -> Bs. | G10: Estado | H10: =Propiedades!H:H -> Disponible | I10: SI | J10: SI | L10: SI | M10: SI
I11: NO | J11: NO
A12: =Propiedades!A:A -> ST-L-0002 | B12: =Propiedades!B:B -> Local Terraza Melchor Urquidi | C12: =Propiedades!C:C -> Alquiler | D12: =Propiedades!D:D -> Zona Norte | E12: =Propiedades!E:E -> 14000 | F12: =Propiedades!F:F -> Bs. | G12: Estado | H12: =Propiedades!H:H -> No Disponible | I12: SI | J12: SI | L12: SI | M12: SI
I13: SI | J13: SI
A14: =Propiedades!A:A -> ST-O-0005 | B14: =Propiedades!B:B -> Oficina 2 Salamanca | C14: =Propiedades!C:C -> Alquiler | D14: =Propiedades!D:D -> Zona Centro | E14: =Propiedades!E:E -> 2200 | F14: =Propiedades!F:F -> Bs. | G14: Estado | H14: =Propiedades!H:H -> Disponible | I14: SI | J14: SI | L14: SI | M14: SI
A15: =Propiedades!A:A -> ST-O-0006 | B15: =Propiedades!B:B -> Oficina 3 Salamanca | C15: =Propiedades!C:C -> Alquiler | D15: =Propiedades!D:D -> Zona Centro | E15: =Propiedades!E:E -> 2200 | F15: =Propiedades!F:F -> Bs. | G15: Estado | H15: =Propiedades!H:H -> Disponible | I15: SI | J15: SI | L15: SI | M15: SI
A16: =Propiedades!A:A -> ST-O-0007 | B16: =Propiedades!B:B -> Oficina 4 Salamanca | C16: =Propiedades!C:C -> Alquiler | D16: =Propiedades!D:D -> Zona Centro | E16: =Propiedades!E:E -> 2200 | F16: =Propiedades!F:F -> Bs. | G16: Estado | H16: =Propiedades!H:H -> Disponible | I16: NO | J16: NO | K16: NO | L16: NO
A17: =Propiedades!A:A -> ST-G-0001 | B17: =Propiedades!B:B -> Garzonier Salamanca | C17: =Propiedades!C:C -> Alquiler | D17: =Propiedades!D:D -> Zona Centro | E17: =Propiedades!E:E -> 2400 | F17: =Propiedades!F:F -> Bs. | G17: Estado | H17: =Propiedades!H:H -> Disponible | I17: NO | J17: NO | L17: NO
I18: NO | J18: NO
A19: =Propiedades!A:A -> ST-E-0001 | B19: =Propiedades!B:B -> Estacionamiento | C19: =Propiedades!C:C -> Venta | D19: =Propiedades!D:D -> Zona Norte | E19: =Propiedades!E:E -> 115000 | F19: =Propiedades!F:F -> Bs. | G19: Estado | H19: =Propiedades!H:H -> Disponible | I19: SI | J19: SI | L19: SI | M19: SI
I20: NO | J20: NO
A21: =Propiedades!A:A -> ST-C-0002 | B21: =Propiedades!B:B -> Casa Chiquicollo | C21: =Propiedades!C:C -> Venta | D21: =Propiedades!D:D -> Zona Chiquicollo | E21: =Propiedades!E:E -> 1980000 | F21: =Propiedades!F:F -> Bs. | G21: Estado | H21: =Propiedades!H:H -> Disponible | I21: SI | J21: SI | L21: SI | M21: SI
I22: NO | J22: NO
A23: =Propiedades!A:A -> ST-C-0004 | B23: =Propiedades!B:B -> Casa Jala | C23: =Propiedades!C:C -> Venta | D23: =Propiedades!D:D -> Zona Norte | E23: =Propiedades!E:E -> 535000 | F23: =Propiedades!F:F -> $ | G23: Estado | H23: =Propiedades!H:H -> Disponible | I23: NO | J23: NO | L23: SI
I24: NO | J24: NO
A25: =Propiedades!A:A -> ST-C-0006 | B25: =Propiedades!B:B -> Casa Valle Hermoso | C25: =Propiedades!C:C -> Venta | D25: =Propiedades!D:D -> Zona Sud | E25: =Propiedades!E:E -> 315000 | F25: =Propiedades!F:F -> $ | G25: Estado | H25: =Propiedades!H:H -> Disponible | I25: SI | J25: SI | K25: SI | L25: SI | M25: SI
A26: =Propiedades!A:A -> ST-C-0007 | B26: =Propiedades!B:B -> Casa Condominio Victoria | C26: =Propiedades!C:C -> Venta | D26: =Propiedades!D:D -> Zona Chiquicollo | E26: =Propiedades!E:E -> 75000 | F26: =Propiedades!F:F -> $ | G26: Estado | H26: =Propiedades!H:H -> Disponible | I26: SI | J26: SI | K26: SI | L26: SI | M26: SI
A27: =Propiedades!A:A -> ST-C-0008 | B27: =Propiedades!B:B -> Casa 1 Condominio Molle | C27: =Propiedades!C:C -> Venta | D27: =Propiedades!D:D -> Zona Nor-Oeste | E27: =Propiedades!E:E -> 1860000 | F27: =Propiedades!F:F -> Bs. | G27: Estado | H27: =Propiedades!H:H -> Disponible | I27: SI | J27: SI | K27: SI | L27: SI | M27: SI
A28: =Propiedades!A:A -> ST-C-0009 | B28: =Propiedades!B:B -> Casa 2 Condominio Molle | C28: =Propiedades!C:C -> Venta | D28: =Propiedades!D:D -> Zona Nor-Oeste | E28: =Propiedades!E:E -> 1800000 | F28: =Propiedades!F:F -> Bs. | G28: Estado | H28: =Propiedades!H:H -> Disponible | I28: SI | J28: SI | K28: SI | L28: SI | M28: SI
A29: =Propiedades!A:A -> ST-C-0010 | B29: =Propiedades!B:B -> Casa 3 Condominio Molle | C29: =Propiedades!C:C -> Venta | D29: =Propiedades!D:D -> Zona Nor-Oeste | E29: =Propiedades!E:E -> 1780000 | F29: =Propiedades!F:F -> Bs. | G29: Estado | H29: =Propiedades!H:H -> Disponible | I29: SI | J29: SI | L29: SI | M29: SI
I30: NO | J30: NO
I31: NO | J31: NO
I32: NO | J32: NO
A33: =Propiedades!A:A -> ST-M-0005 | B33: =Propiedades!B:B -> Monoambiente Auriga | C33: =Propiedades!C:C -> Venta | D33: =Propiedades!D:D -> Zona Norte | E33: =Propiedades!E:E -> 310000 | F33: =Propiedades!F:F -> Bs. | G33: Estado | H33: =Propiedades!H:H -> Retirado | I33: SI | J33: SI | L33: SI | M33: SI
A34: =Propiedades!A:A -> ST-M-0006 | B34: =Propiedades!B:B -> Monoambiente Smart | C34: =Propiedades!C:C -> Venta | D34: =Propiedades!D:D -> Zona Norte | E34: =Propiedades!E:E -> 260000 | F34: =Propiedades!F:F -> Bs. | G34: Estado | H34: =Propiedades!H:H -> No Disponible | I34: NO | J34: NO | K34: NO | L34: NO
I35: NO | J35: NO
I36: NO | J36: NO
I37: NO | J37: NO
A38: =Propiedades!A:A -> ST-M-0008 | B38: =Propiedades!B:B -> Monoambiente Candyl | C38: =Propiedades!C:C -> Venta | D38: =Propiedades!D:D -> Zona Norte | E38: =Propiedades!E:E -> 260000 | F38: =Propiedades!F:F -> Bs. | G38: Estado | H38: =Propiedades!H:H -> Reservado | I38: SI | J38: SI | L38: SI | M38: SI
A39: =Propiedades!A:A -> ST-D-0004 | B39: =Propiedades!B:B -> Departamento Portales | C39: =Propiedades!C:C -> Venta | D39: =Propiedades!D:D -> Zona Norte | E39: =Propiedades!E:E -> 800000 | F39: =Propiedades!F:F -> Bs. | G39: Estado | H39: =Propiedades!H:H -> Disponible | I39: NO | J39: NO | L39: SI
I40: NO | J40: NO
...

Sheet finanzas

Sheet Robles Design
